[2023-09-19 07:51:41,023] {taskinstance.py:896} INFO - Dependencies all met for <TaskInstance: weather_data_pipeline.transform_all_files 2023-09-19T01:20:00+00:00 [queued]>
[2023-09-19 07:51:41,094] {taskinstance.py:896} INFO - Dependencies all met for <TaskInstance: weather_data_pipeline.transform_all_files 2023-09-19T01:20:00+00:00 [queued]>
[2023-09-19 07:51:41,102] {taskinstance.py:1087} INFO - 
--------------------------------------------------------------------------------
[2023-09-19 07:51:41,102] {taskinstance.py:1088} INFO - Starting attempt 1 of 2
[2023-09-19 07:51:41,103] {taskinstance.py:1089} INFO - 
--------------------------------------------------------------------------------
[2023-09-19 07:51:41,235] {taskinstance.py:1107} INFO - Executing <Task(PythonOperator): transform_all_files> on 2023-09-19T01:20:00+00:00
[2023-09-19 07:51:41,403] {standard_task_runner.py:76} INFO - Running: ['***', 'tasks', 'run', 'weather_data_pipeline', 'transform_all_files', '2023-09-19T01:20:00+00:00', '--job-id', '178', '--pool', 'default_pool', '--raw', '--subdir', 'DAGS_FOLDER/weather_data_pipeline.py', '--cfg-path', '/tmp/tmpfrjfmilk', '--error-file', '/tmp/tmpjoit4bqs']
[2023-09-19 07:51:41,415] {standard_task_runner.py:77} INFO - Job 178: Subtask transform_all_files
[2023-09-19 07:51:41,346] {standard_task_runner.py:52} INFO - Started process 1285 to run task
[2023-09-19 07:51:42,017] {logging_mixin.py:104} INFO - Running <TaskInstance: weather_data_pipeline.transform_all_files 2023-09-19T01:20:00+00:00 [running]> on host 92beb7708765
[2023-09-19 07:51:42,881] {taskinstance.py:1302} INFO - Exporting the following env vars:
AIRFLOW_CTX_DAG_OWNER=***
AIRFLOW_CTX_DAG_ID=weather_data_pipeline
AIRFLOW_CTX_TASK_ID=transform_all_files
AIRFLOW_CTX_EXECUTION_DATE=2023-09-19T01:20:00+00:00
AIRFLOW_CTX_DAG_RUN_ID=scheduled__2023-09-19T01:20:00+00:00
[2023-09-19 07:51:42,882] {taskinstance.py:1501} ERROR - Task failed with exception
Traceback (most recent call last):
  File "/home/airflow/.local/lib/python3.6/site-packages/airflow/models/taskinstance.py", line 1157, in _run_raw_task
    self._prepare_and_execute_task_with_callbacks(context, task)
  File "/home/airflow/.local/lib/python3.6/site-packages/airflow/models/taskinstance.py", line 1331, in _prepare_and_execute_task_with_callbacks
    result = self._execute_task(context, task_copy)
  File "/home/airflow/.local/lib/python3.6/site-packages/airflow/models/taskinstance.py", line 1361, in _execute_task
    result = task_copy.execute(context=context)
  File "/home/airflow/.local/lib/python3.6/site-packages/airflow/operators/python.py", line 150, in execute
    return_value = self.execute_callable()
  File "/home/airflow/.local/lib/python3.6/site-packages/airflow/operators/python.py", line 161, in execute_callable
    return self.python_callable(*self.op_args, **self.op_kwargs)
  File "/opt/airflow/dags/weather_data_pipeline.py", line 88, in task3_func
    transform_data_into_csv(filename='fulldata.csv')
  File "/opt/airflow/dags/weather_data_pipeline.py", line 29, in transform_data_into_csv
    files = sorted(os.listdir(parent_folder), reverse=True)
NameError: name 'os' is not defined
[2023-09-19 07:51:42,906] {taskinstance.py:1551} INFO - Marking task as UP_FOR_RETRY. dag_id=weather_data_pipeline, task_id=transform_all_files, execution_date=20230919T012000, start_date=20230919T075141, end_date=20230919T075142
[2023-09-19 07:51:43,359] {local_task_job.py:151} INFO - Task exited with return code 1
