[2023-09-19 07:53:09,280] {taskinstance.py:896} INFO - Dependencies all met for <TaskInstance: weather_data_pipeline.fetch_weather_data 2023-09-19T01:29:00+00:00 [queued]>
[2023-09-19 07:53:09,645] {taskinstance.py:896} INFO - Dependencies all met for <TaskInstance: weather_data_pipeline.fetch_weather_data 2023-09-19T01:29:00+00:00 [queued]>
[2023-09-19 07:53:09,650] {taskinstance.py:1087} INFO - 
--------------------------------------------------------------------------------
[2023-09-19 07:53:09,650] {taskinstance.py:1088} INFO - Starting attempt 1 of 2
[2023-09-19 07:53:09,650] {taskinstance.py:1089} INFO - 
--------------------------------------------------------------------------------
[2023-09-19 07:53:09,841] {taskinstance.py:1107} INFO - Executing <Task(PythonOperator): fetch_weather_data> on 2023-09-19T01:29:00+00:00
[2023-09-19 07:53:10,092] {standard_task_runner.py:76} INFO - Running: ['***', 'tasks', 'run', 'weather_data_pipeline', 'fetch_weather_data', '2023-09-19T01:29:00+00:00', '--job-id', '233', '--pool', 'default_pool', '--raw', '--subdir', 'DAGS_FOLDER/weather_data_pipeline.py', '--cfg-path', '/tmp/tmp9bdx0zcn', '--error-file', '/tmp/tmp2pad2h10']
[2023-09-19 07:53:10,093] {standard_task_runner.py:77} INFO - Job 233: Subtask fetch_weather_data
[2023-09-19 07:53:09,972] {standard_task_runner.py:52} INFO - Started process 1448 to run task
[2023-09-19 07:53:10,709] {logging_mixin.py:104} INFO - Running <TaskInstance: weather_data_pipeline.fetch_weather_data 2023-09-19T01:29:00+00:00 [running]> on host 92beb7708765
[2023-09-19 07:53:11,323] {taskinstance.py:1302} INFO - Exporting the following env vars:
AIRFLOW_CTX_DAG_OWNER=***
AIRFLOW_CTX_DAG_ID=weather_data_pipeline
AIRFLOW_CTX_TASK_ID=fetch_weather_data
AIRFLOW_CTX_EXECUTION_DATE=2023-09-19T01:29:00+00:00
AIRFLOW_CTX_DAG_RUN_ID=scheduled__2023-09-19T01:29:00+00:00
[2023-09-19 07:53:11,559] {taskinstance.py:1501} ERROR - Task failed with exception
Traceback (most recent call last):
  File "/home/airflow/.local/lib/python3.6/site-packages/urllib3/connectionpool.py", line 677, in urlopen
    chunked=chunked,
  File "/home/airflow/.local/lib/python3.6/site-packages/urllib3/connectionpool.py", line 381, in _make_request
    self._validate_conn(conn)
  File "/home/airflow/.local/lib/python3.6/site-packages/urllib3/connectionpool.py", line 978, in _validate_conn
    conn.connect()
  File "/home/airflow/.local/lib/python3.6/site-packages/urllib3/connection.py", line 371, in connect
    ssl_context=context,
  File "/home/airflow/.local/lib/python3.6/site-packages/urllib3/util/ssl_.py", line 386, in ssl_wrap_socket
    return context.wrap_socket(sock, server_hostname=server_hostname)
  File "/usr/local/lib/python3.6/ssl.py", line 407, in wrap_socket
    _context=self, _session=session)
  File "/usr/local/lib/python3.6/ssl.py", line 817, in __init__
    self.do_handshake()
  File "/usr/local/lib/python3.6/ssl.py", line 1077, in do_handshake
    self._sslobj.do_handshake()
  File "/usr/local/lib/python3.6/ssl.py", line 689, in do_handshake
    self._sslobj.do_handshake()
OSError: [Errno 0] Error

During handling of the above exception, another exception occurred:

Traceback (most recent call last):
  File "/home/airflow/.local/lib/python3.6/site-packages/requests/adapters.py", line 449, in send
    timeout=timeout
  File "/home/airflow/.local/lib/python3.6/site-packages/urllib3/connectionpool.py", line 727, in urlopen
    method, url, error=e, _pool=self, _stacktrace=sys.exc_info()[2]
  File "/home/airflow/.local/lib/python3.6/site-packages/urllib3/util/retry.py", line 410, in increment
    raise six.reraise(type(error), error, _stacktrace)
  File "/home/airflow/.local/lib/python3.6/site-packages/urllib3/packages/six.py", line 734, in reraise
    raise value.with_traceback(tb)
  File "/home/airflow/.local/lib/python3.6/site-packages/urllib3/connectionpool.py", line 677, in urlopen
    chunked=chunked,
  File "/home/airflow/.local/lib/python3.6/site-packages/urllib3/connectionpool.py", line 381, in _make_request
    self._validate_conn(conn)
  File "/home/airflow/.local/lib/python3.6/site-packages/urllib3/connectionpool.py", line 978, in _validate_conn
    conn.connect()
  File "/home/airflow/.local/lib/python3.6/site-packages/urllib3/connection.py", line 371, in connect
    ssl_context=context,
  File "/home/airflow/.local/lib/python3.6/site-packages/urllib3/util/ssl_.py", line 386, in ssl_wrap_socket
    return context.wrap_socket(sock, server_hostname=server_hostname)
  File "/usr/local/lib/python3.6/ssl.py", line 407, in wrap_socket
    _context=self, _session=session)
  File "/usr/local/lib/python3.6/ssl.py", line 817, in __init__
    self.do_handshake()
  File "/usr/local/lib/python3.6/ssl.py", line 1077, in do_handshake
    self._sslobj.do_handshake()
  File "/usr/local/lib/python3.6/ssl.py", line 689, in do_handshake
    self._sslobj.do_handshake()
urllib3.exceptions.ProtocolError: ('Connection aborted.', OSError(0, 'Error'))

During handling of the above exception, another exception occurred:

Traceback (most recent call last):
  File "/home/airflow/.local/lib/python3.6/site-packages/airflow/models/taskinstance.py", line 1157, in _run_raw_task
    self._prepare_and_execute_task_with_callbacks(context, task)
  File "/home/airflow/.local/lib/python3.6/site-packages/airflow/models/taskinstance.py", line 1331, in _prepare_and_execute_task_with_callbacks
    result = self._execute_task(context, task_copy)
  File "/home/airflow/.local/lib/python3.6/site-packages/airflow/models/taskinstance.py", line 1361, in _execute_task
    result = task_copy.execute(context=context)
  File "/home/airflow/.local/lib/python3.6/site-packages/airflow/operators/python.py", line 150, in execute
    return_value = self.execute_callable()
  File "/home/airflow/.local/lib/python3.6/site-packages/airflow/operators/python.py", line 161, in execute_callable
    return self.python_callable(*self.op_args, **self.op_kwargs)
  File "/opt/airflow/dags/weather_data_pipeline.py", line 15, in fetch_weather_data
    response = requests.get(URL_TEMPLATE.format(city=city, api_key=API_KEY))
  File "/home/airflow/.local/lib/python3.6/site-packages/requests/api.py", line 76, in get
    return request('get', url, params=params, **kwargs)
  File "/home/airflow/.local/lib/python3.6/site-packages/requests/api.py", line 61, in request
    return session.request(method=method, url=url, **kwargs)
  File "/home/airflow/.local/lib/python3.6/site-packages/requests/sessions.py", line 542, in request
    resp = self.send(prep, **send_kwargs)
  File "/home/airflow/.local/lib/python3.6/site-packages/requests/sessions.py", line 655, in send
    r = adapter.send(request, **kwargs)
  File "/home/airflow/.local/lib/python3.6/site-packages/requests/adapters.py", line 498, in send
    raise ConnectionError(err, request=request)
requests.exceptions.ConnectionError: ('Connection aborted.', OSError(0, 'Error'))
[2023-09-19 07:53:11,590] {taskinstance.py:1551} INFO - Marking task as UP_FOR_RETRY. dag_id=weather_data_pipeline, task_id=fetch_weather_data, execution_date=20230919T012900, start_date=20230919T075309, end_date=20230919T075311
[2023-09-19 07:53:11,816] {local_task_job.py:151} INFO - Task exited with return code 1
