[2023-09-19 08:01:41,122] {taskinstance.py:896} INFO - Dependencies all met for <TaskInstance: weather_data_pipeline.transform_all_files 2023-09-19T01:53:00+00:00 [queued]>
[2023-09-19 08:01:41,340] {taskinstance.py:896} INFO - Dependencies all met for <TaskInstance: weather_data_pipeline.transform_all_files 2023-09-19T01:53:00+00:00 [queued]>
[2023-09-19 08:01:41,340] {taskinstance.py:1087} INFO - 
--------------------------------------------------------------------------------
[2023-09-19 08:01:41,340] {taskinstance.py:1088} INFO - Starting attempt 2 of 2
[2023-09-19 08:01:41,340] {taskinstance.py:1089} INFO - 
--------------------------------------------------------------------------------
[2023-09-19 08:01:41,483] {taskinstance.py:1107} INFO - Executing <Task(PythonOperator): transform_all_files> on 2023-09-19T01:53:00+00:00
[2023-09-19 08:01:41,555] {standard_task_runner.py:52} INFO - Started process 2059 to run task
[2023-09-19 08:01:41,651] {standard_task_runner.py:76} INFO - Running: ['***', 'tasks', 'run', 'weather_data_pipeline', 'transform_all_files', '2023-09-19T01:53:00+00:00', '--job-id', '369', '--pool', 'default_pool', '--raw', '--subdir', 'DAGS_FOLDER/weather_data_pipeline.py', '--cfg-path', '/tmp/tmpg4s08g2c', '--error-file', '/tmp/tmpsgus0l17']
[2023-09-19 08:01:41,652] {standard_task_runner.py:77} INFO - Job 369: Subtask transform_all_files
[2023-09-19 08:01:42,526] {logging_mixin.py:104} INFO - Running <TaskInstance: weather_data_pipeline.transform_all_files 2023-09-19T01:53:00+00:00 [running]> on host 92beb7708765
[2023-09-19 08:01:43,241] {taskinstance.py:1302} INFO - Exporting the following env vars:
AIRFLOW_CTX_DAG_OWNER=***
AIRFLOW_CTX_DAG_ID=weather_data_pipeline
AIRFLOW_CTX_TASK_ID=transform_all_files
AIRFLOW_CTX_EXECUTION_DATE=2023-09-19T01:53:00+00:00
AIRFLOW_CTX_DAG_RUN_ID=scheduled__2023-09-19T01:53:00+00:00
[2023-09-19 08:01:43,242] {taskinstance.py:1501} ERROR - Task failed with exception
Traceback (most recent call last):
  File "/home/airflow/.local/lib/python3.6/site-packages/airflow/models/taskinstance.py", line 1157, in _run_raw_task
    self._prepare_and_execute_task_with_callbacks(context, task)
  File "/home/airflow/.local/lib/python3.6/site-packages/airflow/models/taskinstance.py", line 1331, in _prepare_and_execute_task_with_callbacks
    result = self._execute_task(context, task_copy)
  File "/home/airflow/.local/lib/python3.6/site-packages/airflow/models/taskinstance.py", line 1361, in _execute_task
    result = task_copy.execute(context=context)
  File "/home/airflow/.local/lib/python3.6/site-packages/airflow/operators/python.py", line 150, in execute
    return_value = self.execute_callable()
  File "/home/airflow/.local/lib/python3.6/site-packages/airflow/operators/python.py", line 161, in execute_callable
    return self.python_callable(*self.op_args, **self.op_kwargs)
  File "/opt/airflow/dags/weather_data_pipeline.py", line 91, in task3_func
    transform_data_into_csv(filename='fulldata.csv')
  File "/opt/airflow/dags/weather_data_pipeline.py", line 43, in transform_data_into_csv
    'temperature': data_city['main']['temp'],
TypeError: string indices must be integers
[2023-09-19 08:01:43,328] {taskinstance.py:1551} INFO - Marking task as FAILED. dag_id=weather_data_pipeline, task_id=transform_all_files, execution_date=20230919T015300, start_date=20230919T080141, end_date=20230919T080143
[2023-09-19 08:01:43,888] {local_task_job.py:151} INFO - Task exited with return code 1
