[2023-09-19 08:13:54,664] {taskinstance.py:896} INFO - Dependencies all met for <TaskInstance: weather_data_pipeline.transform_recent_20_files 2023-09-19T08:12:39.127288+00:00 [queued]>
[2023-09-19 08:13:54,709] {taskinstance.py:896} INFO - Dependencies all met for <TaskInstance: weather_data_pipeline.transform_recent_20_files 2023-09-19T08:12:39.127288+00:00 [queued]>
[2023-09-19 08:13:54,710] {taskinstance.py:1087} INFO - 
--------------------------------------------------------------------------------
[2023-09-19 08:13:54,710] {taskinstance.py:1088} INFO - Starting attempt 2 of 2
[2023-09-19 08:13:54,710] {taskinstance.py:1089} INFO - 
--------------------------------------------------------------------------------
[2023-09-19 08:13:54,733] {taskinstance.py:1107} INFO - Executing <Task(PythonOperator): transform_recent_20_files> on 2023-09-19T08:12:39.127288+00:00
[2023-09-19 08:13:54,743] {standard_task_runner.py:52} INFO - Started process 2655 to run task
[2023-09-19 08:13:54,787] {standard_task_runner.py:76} INFO - Running: ['***', 'tasks', 'run', 'weather_data_pipeline', 'transform_recent_20_files', '2023-09-19T08:12:39.127288+00:00', '--job-id', '406', '--pool', 'default_pool', '--raw', '--subdir', 'DAGS_FOLDER/weather_data_pipeline.py', '--cfg-path', '/tmp/tmp3e9sjfua', '--error-file', '/tmp/tmp8e71v2xb']
[2023-09-19 08:13:54,787] {standard_task_runner.py:77} INFO - Job 406: Subtask transform_recent_20_files
[2023-09-19 08:13:54,976] {logging_mixin.py:104} INFO - Running <TaskInstance: weather_data_pipeline.transform_recent_20_files 2023-09-19T08:12:39.127288+00:00 [running]> on host 92beb7708765
[2023-09-19 08:13:55,126] {taskinstance.py:1302} INFO - Exporting the following env vars:
AIRFLOW_CTX_DAG_OWNER=***
AIRFLOW_CTX_DAG_ID=weather_data_pipeline
AIRFLOW_CTX_TASK_ID=transform_recent_20_files
AIRFLOW_CTX_EXECUTION_DATE=2023-09-19T08:12:39.127288+00:00
AIRFLOW_CTX_DAG_RUN_ID=manual__2023-09-19T08:12:39.127288+00:00
[2023-09-19 08:13:55,131] {taskinstance.py:1501} ERROR - Task failed with exception
Traceback (most recent call last):
  File "/home/airflow/.local/lib/python3.6/site-packages/airflow/models/taskinstance.py", line 1157, in _run_raw_task
    self._prepare_and_execute_task_with_callbacks(context, task)
  File "/home/airflow/.local/lib/python3.6/site-packages/airflow/models/taskinstance.py", line 1331, in _prepare_and_execute_task_with_callbacks
    result = self._execute_task(context, task_copy)
  File "/home/airflow/.local/lib/python3.6/site-packages/airflow/models/taskinstance.py", line 1361, in _execute_task
    result = task_copy.execute(context=context)
  File "/home/airflow/.local/lib/python3.6/site-packages/airflow/operators/python.py", line 150, in execute
    return_value = self.execute_callable()
  File "/home/airflow/.local/lib/python3.6/site-packages/airflow/operators/python.py", line 161, in execute_callable
    return self.python_callable(*self.op_args, **self.op_kwargs)
  File "/opt/airflow/dags/weather_data_pipeline.py", line 81, in task2_func
    transform_data_into_csv(n_files=20, filename='data.csv')
  File "/opt/airflow/dags/weather_data_pipeline.py", line 40, in transform_data_into_csv
    for city, data_city in data_temp.items():
AttributeError: 'list' object has no attribute 'items'
[2023-09-19 08:13:55,143] {taskinstance.py:1551} INFO - Marking task as FAILED. dag_id=weather_data_pipeline, task_id=transform_recent_20_files, execution_date=20230919T081239, start_date=20230919T081354, end_date=20230919T081355
[2023-09-19 08:13:55,319] {local_task_job.py:151} INFO - Task exited with return code 1
